Workbook

Sheet README
B1: Vyomaa Energy — P3 & P4 Capital Raise Model
B2: Read me first
B4: Purpose: size senior debt first at SPV3 (P3, 25 MW) and SPV4 (P4, 50 MW), then fund the residual from one HoldCo, and show how HoldCo money reaches each SPV and comes back to investors.
B6: Structure: Investors (promoter, institutional partner) → HoldCo → SPV3 and SPV4 (100% owned). Lenders lend to each SPV.
B7: HoldCo → SPV: equity shares plus CCDs (85% CCD by default; NCD selectable). SPV → HoldCo, in order: CCD / NCD coupon, NCD principal (debt ranks ahead of dividends), dividends capped at distributable profit, capital reduction after senior debt, final-year capital return.
B8: HoldCo funding order: promoter cash → optional HNI pre-COD CCDs → equity bridge → institutional round priced at P3 COD (15% CCPS + 85% partner CCD that mirrors the SPV CCDs).
B10: Basis: unit economics (cost per kWp, yield, tariff, opex, debt terms) are taken from the Arclight lender pack V23 (P3.1: 75 rooftop sites, 9.47 MWp) and scaled to 25 MW and 50 MW.
B11: Replace them with P3 and P4 EPC quotes, yield reports and lender term sheets as they arrive. Yellow cells are the assumptions to confirm first.
B13: Sheets: README · Dashboard · Inputs · P3 Lender View · Funding Plan · Funding Timeline · Sources & Uses · Construction Draws · SPV3 · SPV4 · HoldCo · Checks.
B14: Colour code: blue = input, black = formula, green = link to another sheet, yellow fill = key assumption.
B16: What the switches on Inputs do:
B17: · Financing case (1 base, 2 recommended, 3 worst, 0 custom) sets each SPV's rate and gearing. Draw order per SPV sets construction interest and bridge cost.
... B25: Not legal or tax advice. Instrument choice, lender consent to shareholder-debt servicing, Companies Act limits and RBI rules on financing promoter contribution need counsel's sign-off.

Sheet Dashboard
B1: Vyomaa Energy — P3 (25 MW) & P4 (50 MW) Capital Raise: Dashboard
B2: Debt first at each SPV, HoldCo equity for the residual. All figures live from the model unless marked captured.
B4: Key outputs | C4: SPV3 (P3) | D4: SPV4 (P4) | E4: Portfolio
B5: Capacity (MWp) | C5: ='Sources & Uses'!C6 -> 25 | D5: ='Sources & Uses'!D6 -> 50 | E5: ='Sources & Uses'!E6 -> 75
B6: Construction capex (₹ Cr) | C6: ='Sources & Uses'!C11 -> 80.13265 | D6: ='Sources & Uses'!D11 -> 160.2653 | E6: ='Sources & Uses'!E11 -> 240.39795
B7: Total uses (₹ Cr) | C7: ='Sources & Uses'!C27 -> 81.824918 | D7: ='Sources & Uses'!D27 -> 163.41973 | E7: ='Sources & Uses'!E27 -> 245.24465
B8: Senior debt, sized first (₹ Cr) | C8: ='Sources & Uses'!C19 -> 53.524953 | D8: ='Sources & Uses'!D19 -> 107.04991 | E8: ='Sources & Uses'!E19 -> 160.57486
B9: Gearing | C9: ='Sources & Uses'!C34 -> 0.65414001 | D9: ='Sources & Uses'!D34 -> 0.65506109 | E9: ='Sources & Uses'!E34 -> 0.65475378
B10: Binding constraint | C10: ='Sources & Uses'!C20 -> DSCR, P90 case | D10: ='Sources & Uses'!D20 -> DSCR, P90 case
B11: Construction draw order | C11: ='Sources & Uses'!C25 -> Debt first | D11: ='Sources & Uses'!D25 -> Equity first
B12: Contingent equity vs 70% plan (₹ Cr) | C12: ='Sources & Uses'!C21 -> 3.8374179 | D12: ='Sources & Uses'!D21 -> 7.4985759 | E12: ='Sources & Uses'!E21 -> 11.335994
B13: HoldCo injection into SPV (₹ Cr) | C13: ='Sources & Uses'!C30 -> 28.299966 | D13: ='Sources & Uses'!D30 -> 56.369822 | E13: ='Sources & Uses'!E30 -> 84.669788
B14: as equity shares | C14: ='Sources & Uses'!C31 -> 4.2449948 | D14: ='Sources & Uses'!D31 -> 8.4554734 | E14: ='Sources & Uses'!E31 -> 12.700468
B15: as CCD / NCD | C15: ='Sources & Uses'!C32 -> 24.054971 | D15: ='Sources & Uses'!D32 -> 47.914349 | E15: ='Sources & Uses'!E32 -> 71.96932
B16: Pre-close cash: PMC + PBG margin (₹ Cr) | C16: ='Sources & Uses'!C41 -> 5.39125 | D16: ='Sources & Uses'!D41 -> 10.7825 | E16: ='Sources & Uses'!E41 -> 16.17375
B17: Minimum DSCR, P50 | C17: =SPV3!D31 -> 1.4064783 | D17: =SPV4!D31 -> 1.4064783
B18: Minimum DSCR, P90 | C18: =SPV3!D32 -> 1.3 | D18: =SPV4!D32 -> 1.3
B19: Project IRR, pre-tax | C19: =SPV3!D92 -> 0.15930435 | D19: =SPV4!D92 -> 0.15441507
B20: SPV equity IRR, lender-pack basis | C20: =SPV3!D91 -> 0.14564579 | D20: =SPV4!D91 -> 0.14292302
B21: SPV equity IRR to HoldCo, with instrument limits | C21: =SPV3!D90 -> 0.14114412 | D21: =SPV4!D90 -> 0.13994361
B22: Peak cash trapped in the SPV (₹ Cr) | C22: =SPV3!D95 -> 8.5057283 | D22: =SPV4!D95 -> 13.825459
B24: HoldCo capital raise | E24: Portfolio
B25: Total HoldCo funding need incl. pre-close (₹ Cr) | E25: =HoldCo!D25 -> 98.128686
B26: Promoter cash used (₹ Cr) | E26: =HoldCo!D29 -> 10
B27: Peak equity bridge (₹ Cr) | E27: =HoldCo!D38 -> 36.871689
B28: Bridge interest (₹ Cr) | E28: =HoldCo!D36 -> 1.9979733
B29: Institutional raise at COD (₹ Cr) | E29: =HoldCo!D39 -> 90.126659
B30: as CCPS (₹ Cr) | E30: =HoldCo!D40 -> 13.518999
B31: as partner CCD / NCD (₹ Cr) | E31: =HoldCo!D41 -> 76.607661
B32: Partner share of HoldCo equity | E32: =HoldCo!D107 -> 0.87844039
B33: Promoter share of HoldCo equity | E33: =HoldCo!D108 -> 0.12155961
B34: Promoter share if priced at cost | E34: =HoldCo!D109 -> 0.080529964
B35: Partner IRR / hurdle 15% | E35: =HoldCo!D110 -> 0.14537767
B36: Partner MOIC | E36: =HoldCo!D111 -> 5.0640892
B37: Promoter IRR | E37: =HoldCo!D113 -> 0.094467413
B38: Promoter MOIC | E38: =HoldCo!D114 -> 4.9779834
B39: Peak cash held at HoldCo (₹ Cr) | E39: =HoldCo!D75 -> 0
B40: HoldCo tax, life of project (₹ Cr) | E40: =HoldCo!D59 -> 0.23230653
B41: Peak SPV tax losses carried forward (₹ Cr) | E41: =MAX(SPV3!E45:AD45)+MAX(SPV4!E45:AD45) -> 176.07793
B42: Cash held in the DSRAs at peak; freed by an LC (₹ Cr) | E42: =MAX(SPV3!E56:AD56)+MAX(SPV4!E56:AD56) -> 13.521176
...

Sheet Inputs
B1: Vyomaa Energy — P3 & P4 Capital Raise Model: Inputs
B2: ₹ Cr unless stated (₹1 Cr = ₹10 million). FY = year ending 31 March, labelled by end year (FY2028 = Apr-2027 to Mar-2028).
B3: Legend: blue = input · black = formula · green = link to another sheet · yellow fill = key assumption to confirm before term sheet.
B5: SPV project inputs | C5: SPV3 (P3) | D5: SPV4 (P4) | E5: Unit | F5: Source / note
B6: Capacity | C6: 25 | D6: 50 | E6: MWp | F6: User, 16 Oct 2026
B7: Financial close & construction FY | C7: 2028 | D7: 2029 | E7: FY | F7: Assumption: P3 follows the P3.1 timetable (build Jul–Oct 2027); P4 one year later
B8: Construction start month within the FY (1 = April) | C8: 4 | D8: 4 | E8: month | F8: P3.1: build starts July 2027. P4 assumed July 2028
B9: Months of operation in the construction FY | C9: =MAX(0,12-(C8-1)-C35) -> 5 | D9: =MAX(0,12-(D8-1)-D35) -> 3 | E9: months | F9: Formula: 12 − months before start − construction months
B10: Hard capex (EPC scope) | C10: 27251 | D10: 27251 | E10: ₹/kWp | F10: Arclight lender pack V23, P3.1 (75 rooftop sites, 9.47 MWp): ₹27.25/Wp. Replace with P3/P4 EPC quotes
B11: Developer fee | C11: 0.03 | D11: 0.03 | E11: % of hard capex | F11: Arclight lender pack V23, P3.1 (75 rooftop sites, 9.47 MWp)
B12: Pre-operative cost | C12: 31.67 | D12: 31.67 | E12: ₹ lakh/MWp | F12: Arclight lender pack V23, P3.1 (75 rooftop sites, 9.47 MWp): ₹3.00 Cr ÷ 9.47 MWp (₹4 lakh per site)
B13: Contingency | C13: 0.03 | D13: 0.03 | E13: % of hard capex | F13: Arclight lender pack V23, P3.1 (75 rooftop sites, 9.47 MWp)
B14: Specific yield, year 1, P50 | C14: 1492 | D14: 1492 | E14: kWh/kWp | F14: Arclight lender pack V23, P3.1 (75 rooftop sites, 9.47 MWp): 14,132.6 MWh ÷ 9,471.9 kWp
B15: Annual degradation | C15: 0.004 | D15: 0.004 | E15: % a year | F15: Arclight lender pack V23, P3.1 (75 rooftop sites, 9.47 MWp): generation FY29 → FY30
B16: PPA tariff (flat) | C16: 4.04 | D16: 4.04 | E16: ₹/kWh | F16: Arclight lender pack V23, P3.1 (75 rooftop sites, 9.47 MWp): weighted LOA tariff ₹4.04
B17: PPA term | C17: 25 | D17: 25 | E17: years | F17: Arclight lender pack V23, P3.1 (75 rooftop sites, 9.47 MWp)
B18: All-in opex, year 1 | C18: 932 | D18: 932 | E18: ₹/kWp/yr | F18: Arclight lender pack V23, P3.1 (75 rooftop sites, 9.47 MWp): ₹931.5 (benchmark ₹650–900)
B19: Opex escalation | C19: 0 | D19: 0 | E19: % a year | F19: P3.1 holds opex flat; test 2–4% (Dashboard scenarios)
B20: Inverter replacement | C20: 2354 | D20: 2354 | E20: ₹/kWp | F20: Arclight lender pack V23, P3.1 (75 rooftop sites, 9.47 MWp): ₹2.23 Cr in Oct 2039
B21: Inverter replacement, operating year | C21: 12 | D21: 12 | E21: year | F21: Arclight lender pack V23, P3.1 (75 rooftop sites, 9.47 MWp)
... B25: Corporate tax rate | C25: 0.25168 | D25: 0.25168 | E25: % | F25: Section 115BAA
B27: Senior debt (lent to each SPV) | C27: SPV3 (P3) | D27: SPV4 (P4) | E27: Unit | F27: Source / note
B28: Maximum gearing, custom (used when financing case = 0) | C28: 0.7 | D28: 0.7 | E28: % | F28: Arclight lender pack V23, P3.1 (75 rooftop sites, 9.47 MWp)
B29: Target DSCR for sculpting | C29: 1.3 | D29: 1.3 | E29: x | F29: Arclight lender pack V23, P3.1 (75 rooftop sites, 9.47 MWp)
B30: All-in interest rate, custom (used when financing case = 0) | C30: 0.105 | D30: 0.105 | E30: % a year | F30: Arclight lender pack V23, P3.1 (75 rooftop sites, 9.47 MWp): 6.0% base + 4.5% margin
B31: Repayment tenor after COD | C31: 10 | D31: 10 | E31: years | F31: Arclight lender pack V23, P3.1 (75 rooftop sites, 9.47 MWp)
B32: Arrangement fee | C32: 0.0125 | D32: 0.0125 | E32: % of facility | F32: Arclight lender pack V23, P3.1 (75 rooftop sites, 9.47 MWp)
B33: Commitment fee | C33: 0.01 | D33: 0.01 | E33: % a year on undrawn | F33: Arclight lender pack V23, P3.1 (75 rooftop sites, 9.47 MWp)
B34: Commitment fee period, average | C34: 5.9 | D34: 5.9 | E34: months | F34: Calibrated: P3.1 commitment fee = 0.49% of facility
B35: Construction period | C35: 4 | D35: 6 | E35: months | F35: P3.1: 4-month build. P4 (50 MW) assumed 6 months
B36: Construction draw order: 0 = lowest cost, 1 = equity first, 2 = pro-rata, 3 = debt first | C36: 3 | D36: 0 | E36: switch | F36: P3: debt first (equity is bridge-funded). P4: lowest cost of the three (round cash already raised)
B37: Cost of HoldCo cash drawn into construction | C37: =IF(AND(C92>0,C100=1),C102,C76) -> 0.125 | D37: =C102 -> 0.065 | E37: % a year | F37: P3: equity bridge rate (linked). P4: deposit yield forgone on round cash
B38: Debt sizing case: 1 = P50 base, 2 = P90 lender case | C38: 2 | D38: 2 | E38: switch | F38: Recommendation: size on the lender (P90) case
B39: P90 yield haircut vs P50 | C39: 0.064 | D39: 0.064 | E39: % | F39: 1.282 × σ 5% (P3.1 Monte Carlo yield σ)
B40: DSRA: months of forward debt service | C40: 6 | D40: 6 | E40: months | F40: Arclight lender pack V23, P3.1 (75 rooftop sites, 9.47 MWp)
B41: DSRA form: 1 = cash, 2 = bank LC | C41: 1 | D41: 1 | E41: switch | F41: LC needs lender consent; Dashboard scenario
B42: LC fee | C42: 0.015 | D42: 0.015 | E42: % a year | F42: Assumption (deck: 1–2%)
B44: Financing cases (pick one with the selector in the HoldCo section) | C44: SPV3 (P3) | D44: SPV4 (P4) | E44: Unit | F44: Source / note
B45: Case 1 · Base: all-in rate | C45: 0.105 | D45: 0.105 | E45: % a year | F45: Both SPVs at 10.5%, sized on P90 within a 70% cap
B46: Case 1 · Base: maximum gearing | C46: 0.7 | D46: 0.7 | E46: %
...

Sheet P3 Lender View
B1: P3 Lender View — the numbers behind the debt deck and teaser
B2: Live from SPV3 and Sources & Uses. Stress cases hold the loan and repayment schedule fixed. Edit the blue stress parameters to test others.
B4: Facility
B5: Senior facility (₹ Cr) | C5: ='Sources & Uses'!$C$19 -> 53.524953
B6: Total project cost (₹ Cr) | C6: ='Sources & Uses'!$C$27 -> 81.824918
B7: Gearing | C7: ='Sources & Uses'!$C$34 -> 0.65414001
B8: All-in rate used | C8: =Inputs!$C$51 -> 0.105
B9: Tenor after COD (years) | C9: =Inputs!$C$31 -> 10
B10: Target DSCR for sculpting | C10: =Inputs!$C$29 -> 1.3
B11: Sizing case | C11: =IF(Inputs!$C$38=2,"P90 lender case","P50 base case") -> P90 lender case
B12: Binding constraint | C12: ='Sources & Uses'!$C$20 -> DSCR, P90 case
B13: Construction draw order | C13: ='Sources & Uses'!$C$25 -> Debt first
B14: HoldCo equity into P3 (₹ Cr) | C14: ='Sources & Uses'!$C$30 -> 28.299966
B16: Cover ratios
B17: Minimum DSCR, P50 | C17: =SPV3!D31 -> 1.4064783
B18: Minimum DSCR, P90 | C18: =SPV3!D32 -> 1.3
B19: Average DSCR, P50 | C19: =SPV3!D96 -> 1.4068652
B20: LLCR, P50 | C20: =SUMPRODUCT(SPV3!F16:AD16,SPV3!F20:AD20)/$C$5 -> 1.4067918
B21: LLCR, P90 | C21: =SUMPRODUCT(SPV3!F17:AD17,SPV3!F20:AD20)/$C$5 -> 1.3
B22: PLCR, P50 | C22: =NPV($C$8,SPV3!F16:AD16)/$C$5 -> 2.0026488
B23: Years of PPA left after the loan | C23: =Inputs!$C$17-Inputs!$C$31 -> 15
B25: Annual cover, years 1–10 (₹ Cr)
B26: Operating year | D26: =SPV3!F5 -> 1 | E26: =SPV3!G5 -> 2 | F26: =SPV3!H5 -> 3 | G26: =SPV3!I5 -> 4 | H26: =SPV3!J5 -> 5 | I26: =SPV3!K5 -> 6 | J26: =SPV3!L5 -> 7 | K26: =SPV3!M5 -> 8 | ... M26: =SPV3!O5 -> 10
B27: Financial year | D27: =SPV3!F6 -> 2029 | E27: =SPV3!G6 -> 2030 | F27: =SPV3!H6 -> 2031 | G27: =SPV3!I6 -> 2032 | H27: =SPV3!J6 -> 2033 | I27: =SPV3!K6 -> 2034 | J27: =SPV3!L6 -> 2035 | K27: =SPV3!M6 -> 2036 | ... M27: =SPV3!O6 -> 2038
B28: CFADS, P50 (pre-tax) | D28: =SPV3!F16 -> 12.7392 | E28: =SPV3!G16 -> 12.678923 | F28: =SPV3!H16 -> 12.618888 | G28: =SPV3!I16 -> 12.559092 | H28: =SPV3!J16 -> 12.499536 | I28: =SPV3!K16 -> 12.440217 | J28: =SPV3!L16 -> 12.381137 | K28: =SPV3!M16 -> 12.322292 | ... M28: =SPV3!O16 -> 12.205308
B29: CFADS, P90 | D29: =SPV3!F17 -> 11.774771 | E29: =SPV3!G17 -> 11.718352 | F29: =SPV3!H17 -> 11.662159 | G29: =SPV3!I17 -> 11.60619 | H29: =SPV3!J17 -> 11.550445 | I29: =SPV3!K17 -> 11.494924 | J29: =SPV3!L17 -> 11.439624 | K29: =SPV3!M17 -> 11.384545 | ... M29: =SPV3!O17 -> 11.275048
B30: Senior debt service | D30: =SPV3!F30 -> 9.0575163 | E30: =SPV3!G30 -> 9.014117 | F30: =SPV3!H30 -> 8.9708913 | G30: =SPV3!I30 -> 8.9278385 | H30: =SPV3!J30 -> 8.8849579 | I30: =SPV3!K30 -> 8.8422489 | J30: =SPV3!L30 -> 8.7997106 | K30: =SPV3!M30 -> 8.7573426 | ... M30: =SPV3!O30 -> 8.6731142
B31: DSCR, P50 | D31: =SPV3!F31 -> 1.4064783 | E31: =SPV3!G31 -> 1.406563 | F31: =SPV3!H31 -> 1.4066481 | G31: =SPV3!I31 -> 1.4067338 | H31: =SPV3!J31 -> 1.4068199 | I31: =SPV3!K31 -> 1.4069065 | J31: =SPV3!L31 -> 1.4069936 | K31: =SPV3!M31 -> 1.4070812 | ... M31: =SPV3!O31 -> 1.4072579
B32: DSCR, P90 | D32: =SPV3!F32 -> 1.3 | E32: =SPV3!G32 -> 1.3 | F32: =SPV3!H32 -> 1.3 | G32: =SPV3!I32 -> 1.3 | H32: =SPV3!J32 -> 1.3 | I32: =SPV3!K32 -> 1.3 | J32: =SPV3!L32 -> 1.3 | K32: =SPV3!M32 -> 1.3 | ... M32: =SPV3!O32 -> 1.3
B33: Loan balance, closing | D33: =SPV3!F29 -> 50.087557 | E33: =SPV3!G29 -> 46.332633 | F33: =SPV3!H29 -> 42.226668 | G33: =SPV3!I29 -> 37.73263 | H33: =SPV3!J29 -> 32.809598 | I33: =SPV3!K29 -> 27.412357 | J33: =SPV3!L29 -> 21.490944 | K33: =SPV3!M29 -> 14.99015 | ... M33: =SPV3!O29 -> 0
B35: Downside cases on the same loan (minimum DSCR, years 1–10)
B36: Case | C36: Yield × | D36: Tariff × | E36: Opex × | F36: + rate (bp) | H36: Min DSCR
B37: P50 base | C37: 1 | D37: 1 | E37: 1 | F37: 0 | H37: =N46 -> 1.4064783
B38: P90 yield | C38: =1-Inputs!$C$39 -> 0.936 | D38: 1 | E38: 1 | F38: 0 | H38: =N47 -> 1.3
B39: Tariff −5% | C39: 1 | D39: 0.95 | E39: 1 | F39: 0 | H39: =N48 -> 1.3232921
B40: Opex +10% | C40: 1 | D40: 1 | E40: 1.1 | F40: 0 | H40: =N49 -> 1.3803932
B41: One-year yield −10% (≈ P99) | C41: 0.9 | D41: 1 | E41: 1 | F41: 0 | H41: =N50 -> 1.2396675
B42: Interest +100 bp | C42: 1 | D42: 1 | E42: 1 | F42: 100 | H42: =N51 -> 1.3280007
B43: Combined: P90, tariff −5%, opex +10% | C43: =1-Inputs!$C$39 -> 0.936 | D43: 0.95 | E43: 1.1 | F43: 0 | H43: =N52 -> 1.1947031
B45: DSCR by year under each case | D45: =SPV3!F5 -> 1 | E45: =SPV3!G5 -> 2 | F45: =SPV3!H5 -> 3 | G45: =SPV3!I5 -> 4 | H45: =SPV3!J5 -> 5 | I45: =SPV3!K5 -> 6 | J45: =SPV3!L5 -> 7 | K45: =SPV3!M5 -> 8 | ... M45: =SPV3!O5 -> 10 | N45: Minimum
...

Sheet Funding Plan
B1: Funding Plan — three tracks for P3 and P4, targets, instruments and timeline
B2: Amounts link to the model. Names and cost ranges are from knowledge to mid-2026: confirm each institution's current appetite before outreach.
B4: 1. The three funding tracks (plus P4 debt later)
B5: Track | C5: Ask | D5: Who to approach | E5: Commit by | F5: Money in
B6: 1. P3 senior debt | C6: ="₹"&TEXT('Sources & Uses'!$C$19,"0.0")&" Cr loan, "&TEXT('Sources & Uses'!$C$34,"0%")&" gearing, "&Inputs!$C$31&" years" -> ₹53.5 Cr loan, 65% gearing, 10 years | D6: Green NBFCs first (Tata Cleantech Capital, Ecofy, L&T Finance); test bank pricing (IREDA, SBI, Axis) | E6: Sanction Apr–May 2027 | F6: Drawn in the Jul–Oct 2027 build
B7: 2. P3 pre-COD HNI equity | C7: =IF(Inputs!$C$92=0,"₹35 Cr HoldCo CCDs (switch on in Inputs)","₹"&TEXT(Inputs!$C$92,"0.0")&" Cr HoldCo CCDs, "&TEXT(Inputs!$C$94,"0%")&" cumulative coupon, COD liquidity window") -> ₹35 Cr HoldCo CCDs (switch on in Inputs) | D7: Family offices and HNIs through wealth platforms (360 ONE, Nuvama Private, Kotak Private, ASK, Waterfield) | E7: Subscriptions Mar–Apr 2027 | F7: At P3 close, June 2027
B8: 3. Institutional partner, P3+P4 | C8: ="≈ ₹"&TEXT(HoldCo!$D$39,"0")&" Cr new money"&IF(Inputs!$C$92=0,", plus an option to buy any HNI CCDs at COD",", plus an option to buy the HNI CCDs (≈ ₹"&TEXT(HoldCo!$D$132,"0")&" Cr for 100%)") -> ≈ ₹90 Cr new money, plus an option to buy any HNI CCDs at COD | D8: Climate and infrastructure funds, rooftop platforms, development investors | E8: Commitment letter by P3 close | F8: Round after P3 COD (≈ Apr 2028), priced at COD
B9: 4. P4 senior debt (later) | C9: ="≈ ₹"&TEXT('Sources & Uses'!$D$19,"0")&" Cr" -> ≈ ₹107 Cr | D9: Banks or IREDA, on P3's operating record | E9: FY29 | F9: P4 build
B10: Shared groundwork: promoter-group disclosure note, certified pre-close spend, LOA status of the remaining 15.5 MWp, lender-controlled escrow, ring-fenced board.
B12: 2. Debt providers
B13: Type | C13: Names to approach | D13: All-in cost | E13: Tenor | F13: Sanction time | G13: Credit tolerance | H13: Role for Arclight
B14: Public-sector lenders | C14: IREDA, SBI, Bank of Baroda, Union Bank, Canara Bank; REC and PFC at the margin | D14: 9.5–10.5% | E14: 10–15 yrs | F14: 4–6 months | G14: Strict | H14: Best cost, once a partner is signed
B15: Private banks | C15: Axis, HDFC Bank, ICICI, Kotak, IndusInd, Yes Bank | D15: 10–11% | E15: 7–12 yrs | F15: 3–5 months | G15: Strict | H15: As above; guarantee limits
B16: Green and infra NBFCs | C16: Tata Cleantech Capital, Ecofy, L&T Finance, Aditya Birla Finance, Tata Capital | D16: 10.5–12% | E16: 8–12 yrs | F16: 6–12 weeks | G16: Moderate: lend on project cash flow | H16: First lender for P3; refinance after a year
B17: Private credit funds | C17: Vivriti, Northern Arc, InCred Alternatives, Neo, Nuvama Alternatives, Kotak Alternate Assets | D17: 13–17% | E17: 2–5 yrs | F17: 4–8 weeks | G17: Flexible; secured and costly | H17: Equity bridge or HoldCo loan
B18: Development and foreign lenders | C18: IFC, ADB, FMO, Proparco, DEG, BII, US DFC; SMBC, MUFG, StanChart, DBS | D18: 10–12% hedged | E18: 10–15 yrs | F18: 6–12 months | G18: Strict integrity checks | H18: Mostly via the NBFCs at this size
B20: 3. Equity partners
B21: Type | C21: Names to approach | D21: Return expected | E21: Ticket and terms | F21: Time to close | G21: What they check | H21: Fit
B22: Rooftop and C&I platforms | C22: CleanMax, Fourth Partner Energy, Amplus (Gentari), Radiance Renewables, Sunsure | D22: 11–13% | E22: Full ₹90 Cr; often want control or a forward purchase | F22: 3–6 months | G22: The assets more than the promoter | H22: Strategic route; most certain
B23: Indian climate and infra funds | C23: Eversource Capital, SBICAP Ventures (Neev), Aavishkaar, Kotak Alternate Assets, Nuvama/EAAA | D23: 15–18% | E23: ₹50–150 Cr minority; CCPS or CCD | F23: 4–8 months | G23: Governance, integrity, pipeline | H23: Track 3 lead candidates
B24: Global development and climate investors | C24: BII, Norfund, DEG, FMO, Proparco, ORIX | D24: 13–16% (₹) | E24: Usually $15–25M+ | F24: 6–12 months | G24: Strict integrity and ESG | H24: Platform pitch (P3, P4, P5…)
B25: Family offices and HNIs | C25: Via 360 ONE, Nuvama Private, Kotak Private, ASK, Waterfield, Centrum, Anand Rathi | D25: 12–15% coupon; 18%+ equity | E25: ₹1–25 Cr each; quarterly coupon | F25: 4–10 weeks | G25: Coupon reliability, exit date | H25: Track 2 (pre-COD CCDs)
B27: 4. Which instrument for the HNI tranche
C28: CCD (recommended) | D28: CCPS | E28: NCD
B29: Counted as P3 equity by the lender | C29: Usually, as quasi-equity; confirm in the term sheet | D29: Yes: pure equity | E29: No: borrowed margin
B30: Cash to HNIs before conversion | C30: 12% cumulative coupon from FY30–31 | D30: Little or none for about 10 years | E30: Fixed coupon; no HoldCo cash in construction
B31: HoldCo tax | C31: Deductible: offsets SPV coupons (mirror) | D31: Not deductible: about ₹17 Cr of tax returns | E31: Deductible
B32: Upside | C32: Converts with the pre-COD credit | D32: Full equity upside | E32: None
B33: Exit at the COD round | C33: Sold to the partner at the round price | D33: Same | E33: Repaid from the round, diverting P4 money
B34: HNI tax | C34: Coupon at slab with TDS; 12.5% LTCG on shares after conversion; s.50AA slab on CCD sale | D34: Dividends at slab; 12.5% LTCG after 24 months | E34: Interest at slab
B35: Regulatory catch | C35: Convert within 10 years of issue, else a deposit | D35: None major | E35: Unsecured, unlisted NCDs to individuals are deposits
B37: 5. Construction draw order
C38: Equity first | D38: Pro-rata | E38: Debt first | F38: Selected / lowest cost
B39: P3 total cost (₹ Cr) | C39: ='Construction Draws'!F30 -> 0.97635871 | D39: ='Construction Draws'!F31 -> 0.93188356 | E39: ='Construction Draws'!F32 -> 0.89862394 | F39: ='Construction Draws'!C35&" / "&'Construction Draws'!C39 -> Debt first / Debt first
B40: P4 total cost (₹ Cr) | C40: ='Construction Draws'!F68 -> 2.4446526 | D40: ='Construction Draws'!F69 -> 2.7561076 | E40: ='Construction Draws'!F70 -> 3.0227005 | F40: ='Construction Draws'!C73&" / "&'Construction Draws'!C77 -> Equity first / Equity first
B41: Debt first saves money only while equity is committed but not yet paid in; escrowed cash at close makes equity first cheapest.

Sheet Funding Timeline
B1: Funding Timeline — October 2026 to April 2028
B2: Bars show when each activity runs, by track. Amber = decision or money-in point. Dates are targets for discussion.
B4: Activity | C4: Track | D4: Oct-26 | E4: Nov-26 | F4: Dec-26 | G4: Jan-27 | H4: Feb-27 | I4: Mar-27 | J4: Apr-27 | K4: May-27 | L4: Jun-27 | M4: Jul-27 | N4: Aug-27 | O4: Sep-27 | P4: Oct-27 | Q4: Nov-27 | R4: Dec-27 | S4: Jan-28 | T4: Feb-28 | U4: Mar-28 | V4: Apr-28
B5: Disclosure note, credit clean-up, board and escrow | C5: Groundwork
B6: Information memorandum, data room, model | C6: Groundwork
B7: NBFC indicative terms | C7: 1 · P3 debt
B8: Lead lender, independent engineer report | C8: 1 · P3 debt
B9: Credit approval and loan documents | C9: 1 · P3 debt
B10: P3 financial close | C10: 1 · P3 debt
B11: Build and debt draws (Jul–Oct) | C11: 1 · P3 debt
B12: P3 COD | C12: 1 · P3 debt
B13: HNI soft commitments (aim 1.3–1.5x) | C13: 2 · HNI
B14: HNI subscriptions signed, conditional on close | C14: 2 · HNI
B15: HNI money in at close | C15: 2 · HNI
B16: COD liquidity window: HNIs may sell | C16: 2 · HNI
... B21: P4 loan process (banks / IREDA) | C21: 4 · P4 debt
B23: Amber = decision or money-in point. Dates are targets for discussion.

Sheet Sources & Uses
B1: Sources & Uses and Debt Sizing — per SPV
B2: Debt is sized first: the facility is the lower of 70% gearing and DSCR capacity on the chosen case. HoldCo funds the residual.
B4: ₹ Cr | C4: SPV3 (P3) | D4: SPV4 (P4) | E4: Portfolio
B5: Construction cost
B6: Capacity (MWp) | C6: =Inputs!$C$6 -> 25 | D6: =Inputs!$D$6 -> 50 | E6: =C6+D6 -> 75
B7: Hard capex (EPC) | C7: =Inputs!$C$6*Inputs!$C$10/10000 -> 68.1275 | D7: =Inputs!$D$6*Inputs!$D$10/10000 -> 136.255 | E7: =C7+D7 -> 204.3825
B8: Developer fee | C8: =C7*Inputs!$C$11 -> 2.043825 | D8: =D7*Inputs!$D$11 -> 4.08765 | E8: =C8+D8 -> 6.131475
B9: Pre-operative cost | C9: =Inputs!$C$6*Inputs!$C$12/100 -> 7.9175 | D9: =Inputs!$D$6*Inputs!$D$12/100 -> 15.835 | E9: =C9+D9 -> 23.7525
B10: Contingency | C10: =C7*Inputs!$C$13 -> 2.043825 | D10: =D7*Inputs!$D$13 -> 4.08765 | E10: =C10+D10 -> 6.131475
B11: Construction capex | C11: =SUM(C7:C10) -> 80.13265 | D11: =SUM(D7:D10) -> 160.2653 | E11: =C11+D11 -> 240.39795
B12: Construction capex per kWp (₹) | C12: =C11*10000/C6 -> 32053.06 | D12: =D11*10000/D6 -> 32053.06 | E12: =E11*10000/E6 -> 32053.06
B13: Debt sizing (debt first)
B14: Financing cost factor (IDC + fees, % of facility) | C14: =Inputs!$C$32+Inputs!$C$33*Inputs!$C$34/12+'Construction Draws'!$C$36 -> 0.03161644 | D14: =Inputs!$D$32+Inputs!$D$33*Inputs!$D$34/12+'Construction Draws'!$C$74 -> 0.029466894
B15: A. Gearing-sized debt: 70% of total uses | C15: =Inputs!$C$52*C11/(1-Inputs!$C$52*C14) -> 57.362371 | D15: =Inputs!$D$52*D11/(1-Inputs!$D$52*D14) -> 114.54848 | E15: =C15+D15 -> 171.91085
B16: B. DSCR capacity at target, P50 base case | C16: =SPV3!$D$21 -> 57.921895 | D16: =SPV4!$D$21 -> 115.84379 | E16: =C16+D16 -> 173.76568
B17: C. DSCR capacity at target, P90 lender case | C17: =SPV3!$D$22 -> 53.524953 | D17: =SPV4!$D$22 -> 107.04991 | E17: =C17+D17 -> 160.57486
B18: DSCR capacity on the chosen sizing case | C18: =IF(Inputs!$C$38=2,C17,C16) -> 53.524953 | D18: =IF(Inputs!$D$38=2,D17,D16) -> 107.04991 | E18: =C18+D18 -> 160.57486
B19: Senior debt facility = lower of A and chosen case | C19: =MIN(C15,C18) -> 53.524953 | D19: =MIN(D15,D18) -> 107.04991 | E19: =C19+D19 -> 160.57486
B20: Binding constraint | C20: =IF(C15<=C18,"Gearing 70%",IF(Inputs!$C$38=2,"DSCR, P90 case","DSCR, P50 case")) -> DSCR, P90 case | D20: =IF(D15<=D18,"Gearing 70%",IF(Inputs!$D$38=2,"DSCR, P90 case","DSCR, P50 case")) -> DSCR, P90 case
B21: Equity needed above the 70% plan (contingent equity) | C21: =MAX(0,C15-C19) -> 3.8374179 | D21: =MAX(0,D15-D19) -> 7.4985759 | E21: =C21+D21 -> 11.335994
B22: Uses
B23: Construction capex | C23: =C11 -> 80.13265 | D23: =D11 -> 160.2653 | E23: =C23+D23 -> 240.39795
B24: Interest during construction (chosen draw order) | C24: =C19*'Construction Draws'!$C$36 -> 0.76004218 | D24: =D19*'Construction Draws'!$C$74 -> 1.2899757 | E24: =C24+D24 -> 2.0500178
B25: Construction draw order used | C25: ='Construction Draws'!$C$35 -> Debt first | D25: ='Construction Draws'!$C$73 -> Equity first
B26: Arrangement and commitment fees | C26: =C19*(Inputs!$C$32+Inputs!$C$33*Inputs!$C$34/12) -> 0.93222626 | D26: =D19*(Inputs!$D$32+Inputs!$D$33*Inputs!$D$34/12) -> 1.8644525 | E26: =C26+D26 -> 2.7966788
B27: Total uses (incl. any DSRA funded at COD, row 44) | C27: =C23+C24+C26+C44 -> 81.824918 | D27: =D23+D24+D26+D44 -> 163.41973 | E27: =C27+D27 -> 245.24465
B28: Sources
B29: Senior debt (SPV) | C29: =C19 -> 53.524953 | D29: =D19 -> 107.04991 | E29: =C29+D29 -> 160.57486
B30: HoldCo injection (residual) | C30: =C27-C29 -> 28.299966 | D30: =D27-D29 -> 56.369822 | E30: =C30+D30 -> 84.669788
B31: of which equity shares | C31: =C30*(1-Inputs!$C$55) -> 4.2449948 | D31: =D30*(1-Inputs!$D$55) -> 8.4554734 | E31: =C31+D31 -> 12.700468
B32: of which CCD / NCD | C32: =C30*Inputs!$C$55 -> 24.054971 | D32: =D30*Inputs!$D$55 -> 47.914349 | E32: =C32+D32 -> 71.96932
B33: Total sources | C33: =C29+C30 -> 81.824918 | D33: =D29+D30 -> 163.41973 | E33: =C33+D33 -> 245.24465
B34: Gearing (debt ÷ total uses) | C34: =C29/C27 -> 0.65414001 | D34: =D29/D27 -> 0.65506109 | E34: =E29/E27 -> 0.65475378
B35: Check: sources − uses | C35: =C33-C27 -> 0 | D35: =D33-D27 -> 0 | E35: =C35+D35 -> 0
B36: Pre-close cash (HoldCo-funded before close; PMC and premium are capitalised in the SPV, row 43)
B37: PMC / owner's engineer | C37: =IF(Inputs!$C$66=1,0,Inputs!$C$6*Inputs!$C$65/100) -> 3.985 | D37: =IF(Inputs!$D$66=1,0,Inputs!$D$6*Inputs!$D$65/100) -> 7.97 | E37: =C37+D37 -> 11.955
B38: Performance bank guarantee (non-cash) | C38: =Inputs!$C$6*Inputs!$C$67/10000 -> 5.625 | D38: =Inputs!$D$6*Inputs!$D$67/10000 -> 11.25 | E38: =C38+D38 -> 16.875
B39: Cash margin on the PBG (nil with a surety bond) | C39: =IF(Inputs!$C$106=2,0,C38*Inputs!$C$68) -> 1.40625 | D39: =IF(Inputs!$C$106=2,0,D38*Inputs!$D$68) -> 2.8125 | E39: =C39+D39 -> 4.21875
B40: Surety-bond premium (if used) | C40: =IF(Inputs!$C$106=2,C38*Inputs!$C$107*Inputs!$C$108,0) -> 0 | D40: =IF(Inputs!$C$106=2,D38*Inputs!$C$107*Inputs!$C$108,0) -> 0 | E40: =C40+D40 -> 0
B41: Pre-close cash need | C41: =C37+C39+C40 -> 5.39125 | D41: =D37+D39+D40 -> 10.7825 | E41: =C41+D41 -> 16.17375
...

Sheet Construction Draws
B1: Construction draws — equity first, pro-rata or debt first, per SPV
B2: Monthly. Debt share = lower of max gearing and DSCR capacity ÷ capex. Cost of each order = IDC on debt + carrying cost of HoldCo cash, both to COD. The chosen order feeds Sources & Uses and the HoldCo bridge.
B4: SPV3 (P3)
B5: Construction month | D5: 1 | E5: 2 | F5: 3 | G5: 4 | H5: 5 | I5: 6 | J5: 7 | K5: 8 | L5: 9 | M5: 10 | N5: 11 | O5: 12 | P5: Total
B6: Capex draw profile (input) | D6: 0.05 | E6: 0.15 | F6: 0.3 | G6: 0.5 | H6: 0 | I6: 0 | J6: 0 | K6: 0 | L6: 0 | M6: 0 | N6: 0 | O6: 0 | P6: =SUM(D6:O6) -> 1
B7: Capex drawn (₹ Cr) | D7: =$C$25*D6 -> 4.0066325 | E7: =$C$25*E6 -> 12.019898 | F7: =$C$25*F6 -> 24.039795 | G7: =$C$25*G6 -> 40.066325 | H7: =$C$25*H6 -> 0 | I7: =$C$25*I6 -> 0 | J7: =$C$25*J6 -> 0 | K7: =$C$25*K6 -> 0 | ... O7: =$C$25*O6 -> 0 | P7: =SUM(D7:O7) -> 80.13265
B8: Cumulative capex | D8: =D7 -> 4.0066325 | E8: =D8+E7 -> 16.02653 | F8: =E8+F7 -> 40.066325 | G8: =F8+G7 -> 80.13265 | H8: =G8+H7 -> 80.13265 | I8: =H8+I7 -> 80.13265 | J8: =I8+J7 -> 80.13265 | K8: =J8+K7 -> 80.13265 | L8: =K8+L7 -> 80.13265 | ... O8: =N8+O7 -> 80.13265
B9: 1. Equity first — cumulative debt | D9: =MAX(0,D8-$C$25*(1-$C$26)) -> 0 | E9: =MAX(0,E8-$C$25*(1-$C$26)) -> 0 | F9: =MAX(0,F8-$C$25*(1-$C$26)) -> 13.458628 | G9: =MAX(0,G8-$C$25*(1-$C$26)) -> 53.524953 | H9: =MAX(0,H8-$C$25*(1-$C$26)) -> 53.524953 | I9: =MAX(0,I8-$C$25*(1-$C$26)) -> 53.524953 | J9: =MAX(0,J8-$C$25*(1-$C$26)) -> 53.524953 | K9: =MAX(0,K8-$C$25*(1-$C$26)) -> 53.524953 | ... O9: =MAX(0,O8-$C$25*(1-$C$26)) -> 53.524953
B10: debt drawn | D10: =D9 -> 0 | E10: =E9-D9 -> 0 | F10: =F9-E9 -> 13.458628 | G10: =G9-F9 -> 40.066325 | H10: =H9-G9 -> 0 | I10: =I9-H9 -> 0 | J10: =J9-I9 -> 0 | K10: =K9-J9 -> 0 | L10: =L9-K9 -> 0 | ... O10: =O9-N9 -> 0 | P10: =SUM(D10:O10) -> 53.524953
B11: HoldCo cash drawn | D11: =D7-D10 -> 4.0066325 | E11: =E7-E10 -> 12.019898 | F11: =F7-F10 -> 10.581167 | G11: =G7-G10 -> 0 | H11: =H7-H10 -> 0 | I11: =I7-I10 -> 0 | J11: =J7-J10 -> 0 | K11: =K7-K10 -> 0 | ... O11: =O7-O10 -> 0 | P11: =SUM(D11:O11) -> 26.607697
B12: IDC | D12: =IF(D$5<=Inputs!$C$35,(0+D9)/2*Inputs!$C$51/12,0) -> 0 | E12: =IF(E$5<=Inputs!$C$35,(D9+E9)/2*Inputs!$C$51/12,0) -> 0 | F12: =IF(F$5<=Inputs!$C$35,(E9+F9)/2*Inputs!$C$51/12,0) -> 0.058881497 | G12: =IF(G$5<=Inputs!$C$35,(F9+G9)/2*Inputs!$C$51/12,0) -> 0.29305317 | H12: =IF(H$5<=Inputs!$C$35,(G9+H9)/2*Inputs!$C$51/12,0) -> 0 | I12: =IF(I$5<=Inputs!$C$35,(H9+I9)/2*Inputs!$C$51/12,0) -> 0 | J12: =IF(J$5<=Inputs!$C$35,(I9+J9)/2*Inputs!$C$51/12,0) -> 0 | K12: =IF(K$5<=Inputs!$C$35,(J9+K9)/2*Inputs!$C$51/12,0) -> 0 | L12: =IF(L$5<=Inputs!$C$35,(K9+L9)/2*Inputs!$C$51/12,0) -> 0 | ... O12: =IF(O$5<=Inputs!$C$35,(N9+O9)/2*Inputs!$C$51/12,0) -> 0 | P12: =SUM(D12:O12) -> 0.35193466
B13: carrying cost of HoldCo cash to COD | D13: =IF(D$5<=Inputs!$C$35,D11*Inputs!$C$37*(Inputs!$C$35-D$5+0.5)/12,0) -> 0.14607514 | E13: =IF(E$5<=Inputs!$C$35,E11*Inputs!$C$37*(Inputs!$C$35-E$5+0.5)/12,0) -> 0.31301816 | F13: =IF(F$5<=Inputs!$C$35,F11*Inputs!$C$37*(Inputs!$C$35-F$5+0.5)/12,0) -> 0.16533074 | G13: =IF(G$5<=Inputs!$C$35,G11*Inputs!$C$37*(Inputs!$C$35-G$5+0.5)/12,0) -> 0 | H13: =IF(H$5<=Inputs!$C$35,H11*Inputs!$C$37*(Inputs!$C$35-H$5+0.5)/12,0) -> 0 | I13: =IF(I$5<=Inputs!$C$35,I11*Inputs!$C$37*(Inputs!$C$35-I$5+0.5)/12,0) -> 0 | J13: =IF(J$5<=Inputs!$C$35,J11*Inputs!$C$37*(Inputs!$C$35-J$5+0.5)/12,0) -> 0 | K13: =IF(K$5<=Inputs!$C$35,K11*Inputs!$C$37*(Inputs!$C$35-K$5+0.5)/12,0) -> 0 | ... O13: =IF(O$5<=Inputs!$C$35,O11*Inputs!$C$37*(Inputs!$C$35-O$5+0.5)/12,0) -> 0 | P13: =SUM(D13:O13) -> 0.62442404
B14: 2. Pro-rata — cumulative debt | D14: =D8*$C$26 -> 2.6762476 | E14: =E8*$C$26 -> 10.704991 | F14: =F8*$C$26 -> 26.762476 | G14: =G8*$C$26 -> 53.524953 | H14: =H8*$C$26 -> 53.524953 | I14: =I8*$C$26 -> 53.524953 | J14: =J8*$C$26 -> 53.524953 | K14: =K8*$C$26 -> 53.524953 | ... O14: =O8*$C$26 -> 53.524953
B15: debt drawn | D15: =D14 -> 2.6762476 | E15: =E14-D14 -> 8.0287429 | F15: =F14-E14 -> 16.057486 | G15: =G14-F14 -> 26.762476 | H15: =H14-G14 -> 0 | I15: =I14-H14 -> 0 | J15: =J14-I14 -> 0 | K15: =K14-J14 -> 0 | L15: =L14-K14 -> 0 | ... O15: =O14-N14 -> 0 | P15: =SUM(D15:O15) -> 53.524953
B16: HoldCo cash drawn | D16: =D7-D15 -> 1.3303849 | E16: =E7-E15 -> 3.9911546 | F16: =F7-F15 -> 7.9823091 | G16: =G7-G15 -> 13.303849 | H16: =H7-H15 -> 0 | I16: =I7-I15 -> 0 | J16: =J7-J15 -> 0 | K16: =K7-K15 -> 0 | ... O16: =O7-O15 -> 0 | P16: =SUM(D16:O16) -> 26.607697
B17: IDC | D17: =IF(D$5<=Inputs!$C$35,(0+D14)/2*Inputs!$C$51/12,0) -> 0.011708583 | E17: =IF(E$5<=Inputs!$C$35,(D14+E14)/2*Inputs!$C$51/12,0) -> 0.058542917 | F17: =IF(F$5<=Inputs!$C$35,(E14+F14)/2*Inputs!$C$51/12,0) -> 0.16392017 | G17: =IF(G$5<=Inputs!$C$35,(F14+G14)/2*Inputs!$C$51/12,0) -> 0.3512575 | H17: =IF(H$5<=Inputs!$C$35,(G14+H14)/2*Inputs!$C$51/12,0) -> 0 | I17: =IF(I$5<=Inputs!$C$35,(H14+I14)/2*Inputs!$C$51/12,0) -> 0 | J17: =IF(J$5<=Inputs!$C$35,(I14+J14)/2*Inputs!$C$51/12,0) -> 0 | K17: =IF(K$5<=Inputs!$C$35,(J14+K14)/2*Inputs!$C$51/12,0) -> 0 | L17: =IF(L$5<=Inputs!$C$35,(K14+L14)/2*Inputs!$C$51/12,0) -> 0 | ... O17: =IF(O$5<=Inputs!$C$35,(N14+O14)/2*Inputs!$C$51/12,0) -> 0 | P17: =SUM(D17:O17) -> 0.58542917
B18: carrying cost of HoldCo cash to COD | D18: =IF(D$5<=Inputs!$C$35,D16*Inputs!$C$37*(Inputs!$C$35-D$5+0.5)/12,0) -> 0.048503615 | E18: =IF(E$5<=Inputs!$C$35,E16*Inputs!$C$37*(Inputs!$C$35-E$5+0.5)/12,0) -> 0.10393632 | F18: =IF(F$5<=Inputs!$C$35,F16*Inputs!$C$37*(Inputs!$C$35-F$5+0.5)/12,0) -> 0.12472358 | G18: =IF(G$5<=Inputs!$C$35,G16*Inputs!$C$37*(Inputs!$C$35-G$5+0.5)/12,0) -> 0.069290878 | H18: =IF(H$5<=Inputs!$C$35,H16*Inputs!$C$37*(Inputs!$C$35-H$5+0.5)/12,0) -> 0 | I18: =IF(I$5<=Inputs!$C$35,I16*Inputs!$C$37*(Inputs!$C$35-I$5+0.5)/12,0) -> 0 | J18: =IF(J$5<=Inputs!$C$35,J16*Inputs!$C$37*(Inputs!$C$35-J$5+0.5)/12,0) -> 0 | K18: =IF(K$5<=Inputs!$C$35,K16*Inputs!$C$37*(Inputs!$C$35-K$5+0.5)/12,0) -> 0 | ... O18: =IF(O$5<=Inputs!$C$35,O16*Inputs!$C$37*(Inputs!$C$35-O$5+0.5)/12,0) -> 0 | P18: =SUM(D18:O18) -> 0.34645439
B19: 3. Debt first — cumulative debt | D19: =MIN(D8,$C$27) -> 4.0066325 | E19: =MIN(E8,$C$27) -> 16.02653 | F19: =MIN(F8,$C$27) -> 40.066325 | G19: =MIN(G8,$C$27) -> 53.524953 | H19: =MIN(H8,$C$27) -> 53.524953 | I19: =MIN(I8,$C$27) -> 53.524953 | J19: =MIN(J8,$C$27) -> 53.524953 | K19: =MIN(K8,$C$27) -> 53.524953 | ... O19: =MIN(O8,$C$27) -> 53.524953
B20: debt drawn | D20: =D19 -> 4.0066325 | E20: =E19-D19 -> 12.019898 | F20: =F19-E19 -> 24.039795 | G20: =G19-F19 -> 13.458628 | H20: =H19-G19 -> 0 | I20: =I19-H19 -> 0 | J20: =J19-I19 -> 0 | K20: =K19-J19 -> 0 | L20: =L19-K19 -> 0 | ... O20: =O19-N19 -> 0 | P20: =SUM(D20:O20) -> 53.524953
B21: HoldCo cash drawn | D21: =D7-D20 -> 0 | E21: =E7-E20 -> 0 | F21: =F7-F20 -> 0 | G21: =G7-G20 -> 26.607697 | H21: =H7-H20 -> 0 | I21: =I7-I20 -> 0 | J21: =J7-J20 -> 0 | K21: =K7-K20 -> 0 | ... O21: =O7-O20 -> 0 | P21: =SUM(D21:O21) -> 26.607697
B22: IDC | D22: =IF(D$5<=Inputs!$C$35,(0+D19)/2*Inputs!$C$51/12,0) -> 0.017529017 | E22: =IF(E$5<=Inputs!$C$35,(D19+E19)/2*Inputs!$C$51/12,0) -> 0.087645086 | F22: =IF(F$5<=Inputs!$C$35,(E19+F19)/2*Inputs!$C$51/12,0) -> 0.24540624 | G22: =IF(G$5<=Inputs!$C$35,(F19+G19)/2*Inputs!$C$51/12,0) -> 0.40946184 | H22: =IF(H$5<=Inputs!$C$35,(G19+H19)/2*Inputs!$C$51/12,0) -> 0 | I22: =IF(I$5<=Inputs!$C$35,(H19+I19)/2*Inputs!$C$51/12,0) -> 0 | J22: =IF(J$5<=Inputs!$C$35,(I19+J19)/2*Inputs!$C$51/12,0) -> 0 | K22: =IF(K$5<=Inputs!$C$35,(J19+K19)/2*Inputs!$C$51/12,0) -> 0 | L22: =IF(L$5<=Inputs!$C$35,(K19+L19)/2*Inputs!$C$51/12,0) -> 0 | ... O22: =IF(O$5<=Inputs!$C$35,(N19+O19)/2*Inputs!$C$51/12,0) -> 0 | P22: =SUM(D22:O22) -> 0.76004218
B23: carrying cost of HoldCo cash to COD | D23: =IF(D$5<=Inputs!$C$35,D21*Inputs!$C$37*(Inputs!$C$35-D$5+0.5)/12,0) -> 0 | E23: =IF(E$5<=Inputs!$C$35,E21*Inputs!$C$37*(Inputs!$C$35-E$5+0.5)/12,0) -> 0 | F23: =IF(F$5<=Inputs!$C$35,F21*Inputs!$C$37*(Inputs!$C$35-F$5+0.5)/12,0) -> 0 | G23: =IF(G$5<=Inputs!$C$35,G21*Inputs!$C$37*(Inputs!$C$35-G$5+0.5)/12,0) -> 0.13858176 | H23: =IF(H$5<=Inputs!$C$35,H21*Inputs!$C$37*(Inputs!$C$35-H$5+0.5)/12,0) -> 0 | I23: =IF(I$5<=Inputs!$C$35,I21*Inputs!$C$37*(Inputs!$C$35-I$5+0.5)/12,0) -> 0 | J23: =IF(J$5<=Inputs!$C$35,J21*Inputs!$C$37*(Inputs!$C$35-J$5+0.5)/12,0) -> 0 | K23: =IF(K$5<=Inputs!$C$35,K21*Inputs!$C$37*(Inputs!$C$35-K$5+0.5)/12,0) -> 0 | ... O23: =IF(O$5<=Inputs!$C$35,O21*Inputs!$C$37*(Inputs!$C$35-O$5+0.5)/12,0) -> 0 | P23: =SUM(D23:O23) -> 0.13858176
B25: Construction capex (₹ Cr) | C25: ='Sources & Uses'!$C$11 -> 80.13265
B26: Debt share of capex | C26: =MIN(Inputs!$C$52,'Sources & Uses'!$C$18/'Sources & Uses'!$C$11) -> 0.66795436
B27: Debt during construction (₹ Cr) | C27: =C25*C26 -> 53.524953
B29: Draw order | D29: IDC | E29: Cash carrying cost | F29: Total cost | G29: Equity-weighted month | H29: HoldCo cash by month 2
B30: 1. Equity first | D30: =P12 -> 0.35193466 | E30: =P13 -> 0.62442404 | F30: =D30+E30 -> 0.97635871 | G30: =IF(P11=0,0,SUMPRODUCT($D$5:$O$5,D11:O11)/P11) -> 2.2470915 | H30: =SUM(D11:E11) -> 16.02653
B31: 2. Pro-rata | D31: =P17 -> 0.58542917 | E31: =P18 -> 0.34645439 | F31: =D31+E31 -> 0.93188356 | G31: =IF(P16=0,0,SUMPRODUCT($D$5:$O$5,D16:O16)/P16) -> 3.25 | H31: =SUM(D16:E16) -> 5.3215394
B32: 3. Debt first | D32: =P22 -> 0.76004218 | E32: =P23 -> 0.13858176 | F32: =D32+E32 -> 0.89862394 | G32: =IF(P21=0,0,SUMPRODUCT($D$5:$O$5,D21:O21)/P21) -> 4 | H32: =SUM(D21:E21) -> 0
B34: Selected draw order (index) | C34: =IF(Inputs!$C$36=0,MATCH(MIN(F30:F32),F30:F32,0),Inputs!$C$36) -> 3
B35: Selected draw order | C35: =CHOOSE(C34,"Equity first","Pro-rata","Debt first") -> Debt first
B36: IDC as % of construction debt | C36: =IF($C$27=0,0,INDEX(D30:D32,C34)/$C$27) -> 0.014199773
B37: Equity-weighted draw month | C37: =INDEX(G30:G32,C34) -> 4
B38: Bridge outstanding in FC year (fraction of year) | C38: =MAX(0,(12-(Inputs!$C$8-1)-C37+0.5)/12) -> 0.45833333
B39: Lowest-cost draw order (for comparison) | C39: =CHOOSE(MATCH(MIN(F30:F32),F30:F32,0),"Equity first","Pro-rata","Debt first") -> Debt first
B42: SPV4 (P4)
B43: Construction month | D43: 1 | E43: 2 | F43: 3 | G43: 4 | H43: 5 | I43: 6 | J43: 7 | K43: 8 | L43: 9 | M43: 10 | N43: 11 | O43: 12 | P43: Total
B44: Capex draw profile (input) | D44: 0.05 | E44: 0.1 | F44: 0.15 | G44: 0.2 | H44: 0.25 | I44: 0.25 | J44: 0 | K44: 0 | L44: 0 | M44: 0 | N44: 0 | O44: 0 | P44: =SUM(D44:O44) -> 1
B45: Capex drawn (₹ Cr) | D45: =$C$63*D44 -> 8.013265 | E45: =$C$63*E44 -> 16.02653 | F45: =$C$63*F44 -> 24.039795 | G45: =$C$63*G44 -> 32.05306 | H45: =$C$63*H44 -> 40.066325 | I45: =$C$63*I44 -> 40.066325 | J45: =$C$63*J44 -> 0 | K45: =$C$63*K44 -> 0 | ... O45: =$C$63*O44 -> 0 | P45: =SUM(D45:O45) -> 160.2653
B46: Cumulative capex | D46: =D45 -> 8.013265 | E46: =D46+E45 -> 24.039795 | F46: =E46+F45 -> 48.07959 | G46: =F46+G45 -> 80.13265 | H46: =G46+H45 -> 120.19898 | I46: =H46+I45 -> 160.2653 | J46: =I46+J45 -> 160.2653 | K46: =J46+K45 -> 160.2653 | L46: =K46+L45 -> 160.2653 | ... O46: =N46+O45 -> 160.2653
...

Sheet SPV3
B1: SPV3 (P3) — Annual operations, senior debt and cash to HoldCo
B2: Year 0 is the construction FY (debt drawn at COD, stub months of operation). Columns E:AD = years 0–25. Column D = total or key result.
B4: Timeline
B5: Year index (0 = construction FY) | D5: Total / result | E5: 0 | F5: =E5+1 -> 1 | G5: =F5+1 -> 2 | H5: =G5+1 -> 3 | I5: =H5+1 -> 4 | J5: =I5+1 -> 5 | K5: =J5+1 -> 6 | L5: =K5+1 -> 7 | M5: =L5+1 -> 8 | ... AD5: =AC5+1 -> 25
B6: Financial year | E6: =Inputs!$C$7+E5 -> 2028 | F6: =Inputs!$C$7+F5 -> 2029 | G6: =Inputs!$C$7+G5 -> 2030 | H6: =Inputs!$C$7+H5 -> 2031 | I6: =Inputs!$C$7+I5 -> 2032 | J6: =Inputs!$C$7+J5 -> 2033 | K6: =Inputs!$C$7+K5 -> 2034 | L6: =Inputs!$C$7+L5 -> 2035 | ... AD6: =Inputs!$C$7+AD5 -> 2053
B7: Operating fraction of year | E7: =IF(E5=0,Inputs!$C$9/12,IF(E5<Inputs!$C$17,1,IF(E5=Inputs!$C$17,1-Inputs!$C$9/12,0))) -> 0.41666667 | F7: =IF(F5=0,Inputs!$C$9/12,IF(F5<Inputs!$C$17,1,IF(F5=Inputs!$C$17,1-Inputs!$C$9/12,0))) -> 1 | G7: =IF(G5=0,Inputs!$C$9/12,IF(G5<Inputs!$C$17,1,IF(G5=Inputs!$C$17,1-Inputs!$C$9/12,0))) -> 1 | H7: =IF(H5=0,Inputs!$C$9/12,IF(H5<Inputs!$C$17,1,IF(H5=Inputs!$C$17,1-Inputs!$C$9/12,0))) -> 1 | I7: =IF(I5=0,Inputs!$C$9/12,IF(I5<Inputs!$C$17,1,IF(I5=Inputs!$C$17,1-Inputs!$C$9/12,0))) -> 1 | J7: =IF(J5=0,Inputs!$C$9/12,IF(J5<Inputs!$C$17,1,IF(J5=Inputs!$C$17,1-Inputs!$C$9/12,0))) -> 1 | K7: =IF(K5=0,Inputs!$C$9/12,IF(K5<Inputs!$C$17,1,IF(K5=Inputs!$C$17,1-Inputs!$C$9/12,0))) -> 1 | L7: =IF(L5=0,Inputs!$C$9/12,IF(L5<Inputs!$C$17,1,IF(L5=Inputs!$C$17,1-Inputs!$C$9/12,0))) -> 1 | ... AD7: =IF(AD5=0,Inputs!$C$9/12,IF(AD5<Inputs!$C$17,1,IF(AD5=Inputs!$C$17,1-Inputs!$C$9/12,0))) -> 0.58333333
B8: Repayment flag | E8: =IF(AND(E5>=1,E5<=Inputs!$C$31),1,0) -> 0 | F8: =IF(AND(F5>=1,F5<=Inputs!$C$31),1,0) -> 1 | G8: =IF(AND(G5>=1,G5<=Inputs!$C$31),1,0) -> 1 | H8: =IF(AND(H5>=1,H5<=Inputs!$C$31),1,0) -> 1 | I8: =IF(AND(I5>=1,I5<=Inputs!$C$31),1,0) -> 1 | J8: =IF(AND(J5>=1,J5<=Inputs!$C$31),1,0) -> 1 | K8: =IF(AND(K5>=1,K5<=Inputs!$C$31),1,0) -> 1 | L8: =IF(AND(L5>=1,L5<=Inputs!$C$31),1,0) -> 1 | ... AD8: =IF(AND(AD5>=1,AD5<=Inputs!$C$31),1,0) -> 0
B9: Operations
B10: Degradation factor | E10: =(1-Inputs!$C$15)^MAX(0,E5-1) -> 1 | F10: =(1-Inputs!$C$15)^MAX(0,F5-1) -> 1 | G10: =(1-Inputs!$C$15)^MAX(0,G5-1) -> 0.996 | H10: =(1-Inputs!$C$15)^MAX(0,H5-1) -> 0.992016 | I10: =(1-Inputs!$C$15)^MAX(0,I5-1) -> 0.98804794 | J10: =(1-Inputs!$C$15)^MAX(0,J5-1) -> 0.98409574 | K10: =(1-Inputs!$C$15)^MAX(0,K5-1) -> 0.98015936 | L10: =(1-Inputs!$C$15)^MAX(0,L5-1) -> 0.97623872 | ... AD10: =(1-Inputs!$C$15)^MAX(0,AD5-1) -> 0.90828914
B11: Generation, P50 | C11: MWh | D11: =SUM(E11:AD11) -> 890508.28 | E11: =Inputs!$C$6*Inputs!$C$14*E10*E7 -> 15541.667 | F11: =Inputs!$C$6*Inputs!$C$14*F10*F7 -> 37300 | G11: =Inputs!$C$6*Inputs!$C$14*G10*G7 -> 37150.8 | H11: =Inputs!$C$6*Inputs!$C$14*H10*H7 -> 37002.197 | I11: =Inputs!$C$6*Inputs!$C$14*I10*I7 -> 36854.188 | J11: =Inputs!$C$6*Inputs!$C$14*J10*J7 -> 36706.771 | K11: =Inputs!$C$6*Inputs!$C$14*K10*K7 -> 36559.944 | L11: =Inputs!$C$6*Inputs!$C$14*L10*L7 -> 36413.704 | ... AD11: =Inputs!$C$6*Inputs!$C$14*AD10*AD7 -> 19762.858
B12: Generation, P90 | C12: MWh | D12: =SUM(E12:AD12) -> 833515.75 | E12: =E11*(1-Inputs!$C$39) -> 14547 | F12: =F11*(1-Inputs!$C$39) -> 34912.8 | G12: =G11*(1-Inputs!$C$39) -> 34773.149 | H12: =H11*(1-Inputs!$C$39) -> 34634.056 | I12: =I11*(1-Inputs!$C$39) -> 34495.52 | J12: =J11*(1-Inputs!$C$39) -> 34357.538 | K12: =K11*(1-Inputs!$C$39) -> 34220.108 | L12: =L11*(1-Inputs!$C$39) -> 34083.227 | ... AD12: =AD11*(1-Inputs!$C$39) -> 18498.035
B13: Revenue, P50 | C13: ₹ Cr | D13: =SUM(E13:AD13) -> 359.76535 | E13: =E11*Inputs!$C$16/10000 -> 6.2788333 | F13: =F11*Inputs!$C$16/10000 -> 15.0692 | G13: =G11*Inputs!$C$16/10000 -> 15.008923 | H13: =H11*Inputs!$C$16/10000 -> 14.948888 | I13: =I11*Inputs!$C$16/10000 -> 14.889092 | J13: =J11*Inputs!$C$16/10000 -> 14.829536 | K13: =K11*Inputs!$C$16/10000 -> 14.770217 | L13: =L11*Inputs!$C$16/10000 -> 14.711137 | ... AD13: =AD11*Inputs!$C$16/10000 -> 7.9841946
B14: Revenue, P90 | C14: ₹ Cr | D14: =SUM(E14:AD14) -> 336.74036 | E14: =E12*Inputs!$C$16/10000 -> 5.876988 | F14: =F12*Inputs!$C$16/10000 -> 14.104771 | G14: =G12*Inputs!$C$16/10000 -> 14.048352 | H14: =H12*Inputs!$C$16/10000 -> 13.992159 | I14: =I12*Inputs!$C$16/10000 -> 13.93619 | J14: =J12*Inputs!$C$16/10000 -> 13.880445 | K14: =K12*Inputs!$C$16/10000 -> 13.824924 | L14: =L12*Inputs!$C$16/10000 -> 13.769624 | ... AD14: =AD12*Inputs!$C$16/10000 -> 7.4732061
B15: Operating cost | C15: ₹ Cr | D15: =SUM(E15:AD15) -> 58.25 | E15: =Inputs!$C$6*Inputs!$C$18*(1+Inputs!$C$19)^MAX(0,E5-1)*E7/10000 -> 0.97083333 | F15: =Inputs!$C$6*Inputs!$C$18*(1+Inputs!$C$19)^MAX(0,F5-1)*F7/10000 -> 2.33 | G15: =Inputs!$C$6*Inputs!$C$18*(1+Inputs!$C$19)^MAX(0,G5-1)*G7/10000 -> 2.33 | H15: =Inputs!$C$6*Inputs!$C$18*(1+Inputs!$C$19)^MAX(0,H5-1)*H7/10000 -> 2.33 | I15: =Inputs!$C$6*Inputs!$C$18*(1+Inputs!$C$19)^MAX(0,I5-1)*I7/10000 -> 2.33 | J15: =Inputs!$C$6*Inputs!$C$18*(1+Inputs!$C$19)^MAX(0,J5-1)*J7/10000 -> 2.33 | K15: =Inputs!$C$6*Inputs!$C$18*(1+Inputs!$C$19)^MAX(0,K5-1)*K7/10000 -> 2.33 | L15: =Inputs!$C$6*Inputs!$C$18*(1+Inputs!$C$19)^MAX(0,L5-1)*L7/10000 -> 2.33 | ... AD15: =Inputs!$C$6*Inputs!$C$18*(1+Inputs!$C$19)^MAX(0,AD5-1)*AD7/10000 -> 1.3591667
B16: EBITDA, P50 (pre-tax CFADS) | C16: ₹ Cr | D16: =SUM(E16:AD16) -> 301.51535 | E16: =E13-E15 -> 5.308 | F16: =F13-F15 -> 12.7392 | G16: =G13-G15 -> 12.678923 | H16: =H13-H15 -> 12.618888 | I16: =I13-I15 -> 12.559092 | J16: =J13-J15 -> 12.499536 | K16: =K13-K15 -> 12.440217 | L16: =L13-L15 -> 12.381137 | ... AD16: =AD13-AD15 -> 6.6250279
B17: EBITDA, P90 (lender case) | C17: ₹ Cr | D17: =SUM(E17:AD17) -> 278.49036 | E17: =E14-E15 -> 4.9061547 | F17: =F14-F15 -> 11.774771 | G17: =G14-G15 -> 11.718352 | H17: =H14-H15 -> 11.662159 | I17: =I14-I15 -> 11.60619 | J17: =J14-J15 -> 11.550445 | K17: =K14-K15 -> 11.494924 | L17: =L14-L15 -> 11.439624 | ... AD17: =AD14-AD15 -> 6.1140395
B18: Debt sizing — debt first, sculpted to the target DSCR
B19: CFADS on the chosen sizing case | C19: ₹ Cr | E19: =IF(Inputs!$C$38=2,E17,E16)*E8 -> 0 | F19: =IF(Inputs!$C$38=2,F17,F16)*F8 -> 11.774771 | G19: =IF(Inputs!$C$38=2,G17,G16)*G8 -> 11.718352 | H19: =IF(Inputs!$C$38=2,H17,H16)*H8 -> 11.662159 | I19: =IF(Inputs!$C$38=2,I17,I16)*I8 -> 11.60619 | J19: =IF(Inputs!$C$38=2,J17,J16)*J8 -> 11.550445 | K19: =IF(Inputs!$C$38=2,K17,K16)*K8 -> 11.494924 | L19: =IF(Inputs!$C$38=2,L17,L16)*L8 -> 11.439624 | ... AD19: =IF(Inputs!$C$38=2,AD17,AD16)*AD8 -> 0
B20: Discount factor at the loan rate | E20: =IF(E8=1,1/(1+Inputs!$C$51)^E5,0) -> 0 | F20: =IF(F8=1,1/(1+Inputs!$C$51)^F5,0) -> 0.90497738 | G20: =IF(G8=1,1/(1+Inputs!$C$51)^G5,0) -> 0.81898405 | H20: =IF(H8=1,1/(1+Inputs!$C$51)^H5,0) -> 0.74116204 | I20: =IF(I8=1,1/(1+Inputs!$C$51)^I5,0) -> 0.67073487 | J20: =IF(J8=1,1/(1+Inputs!$C$51)^J5,0) -> 0.60699989 | K20: =IF(K8=1,1/(1+Inputs!$C$51)^K5,0) -> 0.54932116 | L20: =IF(L8=1,1/(1+Inputs!$C$51)^L5,0) -> 0.49712323 | ... AD20: =IF(AD8=1,1/(1+Inputs!$C$51)^AD5,0) -> 0
B21: PV of debt service capacity, P50 | C21: ₹ Cr | D21: =SUM(E21:AD21) -> 57.921895 | E21: =E16*E8/Inputs!$C$29*E20 -> 0 | F21: =F16*F8/Inputs!$C$29*F20 -> 8.8682214 | G21: =G16*G8/Inputs!$C$29*G20 -> 7.9875661 | H21: =H16*H8/Inputs!$C$29*H20 -> 7.1943387 | I21: =I16*I8/Inputs!$C$29*I20 -> 6.4798623 | J21: =J16*J8/Inputs!$C$29*J20 -> 5.8363205 | K21: =K16*K8/Inputs!$C$29*K20 -> 5.2566729 | L21: =L16*L8/Inputs!$C$29*L20 -> 4.7345773 | ... AD21: =AD16*AD8/Inputs!$C$29*AD20 -> 0
B22: PV of debt service capacity, P90 | C22: ₹ Cr | D22: =SUM(E22:AD22) -> 53.524953 | E22: =E17*E8/Inputs!$C$29*E20 -> 0 | F22: =F17*F8/Inputs!$C$29*F20 -> 8.1968473 | G22: =G17*G8/Inputs!$C$29*G20 -> 7.3824181 | H22: =H17*H8/Inputs!$C$29*H20 -> 6.6488841 | I22: =I17*I8/Inputs!$C$29*I20 -> 5.9882126 | J22: =J17*J8/Inputs!$C$29*J20 -> 5.3931685 | K22: =K17*K8/Inputs!$C$29*K20 -> 4.8572344 | L22: =L17*L8/Inputs!$C$29*L20 -> 4.3745405 | ... AD22: =AD17*AD8/Inputs!$C$29*AD20 -> 0
B23: Scheduled debt service (sculpted) | C23: ₹ Cr | D23: =SUM(E23:AD23) -> 88.642881 | E23: =IF('Sources & Uses'!$C$18>0,E19/Inputs!$C$29*'Sources & Uses'!$C$19/'Sources & Uses'!$C$18,0) -> 0 | F23: =IF('Sources & Uses'!$C$18>0,F19/Inputs!$C$29*'Sources & Uses'!$C$19/'Sources & Uses'!$C$18,0) -> 9.0575163 | G23: =IF('Sources & Uses'!$C$18>0,G19/Inputs!$C$29*'Sources & Uses'!$C$19/'Sources & Uses'!$C$18,0) -> 9.014117 | H23: =IF('Sources & Uses'!$C$18>0,H19/Inputs!$C$29*'Sources & Uses'!$C$19/'Sources & Uses'!$C$18,0) -> 8.9708913 | I23: =IF('Sources & Uses'!$C$18>0,I19/Inputs!$C$29*'Sources & Uses'!$C$19/'Sources & Uses'!$C$18,0) -> 8.9278385 | J23: =IF('Sources & Uses'!$C$18>0,J19/Inputs!$C$29*'Sources & Uses'!$C$19/'Sources & Uses'!$C$18,0) -> 8.8849579 | K23: =IF('Sources & Uses'!$C$18>0,K19/Inputs!$C$29*'Sources & Uses'!$C$19/'Sources & Uses'!$C$18,0) -> 8.8422489 | L23: =IF('Sources & Uses'!$C$18>0,L19/Inputs!$C$29*'Sources & Uses'!$C$19/'Sources & Uses'!$C$18,0) -> 8.7997106 | ... AD23: =IF('Sources & Uses'!$C$18>0,AD19/Inputs!$C$29*'Sources & Uses'!$C$19/'Sources & Uses'!$C$18,0) -> 0
B24: Senior debt
B25: Opening balance | C25: ₹ Cr | E25: 0 | F25: =E29 -> 53.524953 | G25: =F29 -> 50.087557 | H25: =G29 -> 46.332633 | I25: =H29 -> 42.226668 | J25: =I29 -> 37.73263 | K25: =J29 -> 32.809598 | L25: =K29 -> 27.412357 | M25: =L29 -> 21.490944 | ... AD25: =AC29 -> 0
B26: Drawdown | C26: ₹ Cr | D26: =SUM(E26:AD26) -> 53.524953 | E26: ='Sources & Uses'!$C$19 -> 53.524953 | F26: 0 | G26: 0 | H26: 0 | I26: 0 | J26: 0 | K26: 0 | L26: 0 | M26: 0 | N26: 0 | O26: 0 | P26: 0 | Q26: 0 | R26: 0 | S26: 0 | T26: 0 | U26: 0 | V26: 0 | W26: 0 | X26: 0 | Y26: 0 | Z26: 0 | AA26: 0 | AB26: 0 | AC26: 0 | AD26: 0
B27: Interest (post-COD) | C27: ₹ Cr | D27: =SUM(E27:AD27) -> 37.459645 | E27: ='Sources & Uses'!$C$19*Inputs!$C$51*Inputs!$C$9/12 -> 2.3417167 | F27: =F25*Inputs!$C$51 -> 5.62012 | G27: =G25*Inputs!$C$51 -> 5.2591934 | H27: =H25*Inputs!$C$51 -> 4.8649265 | I27: =I25*Inputs!$C$51 -> 4.4338002 | J27: =J25*Inputs!$C$51 -> 3.9619261 | K27: =K25*Inputs!$C$51 -> 3.4450078 | L27: =L25*Inputs!$C$51 -> 2.8782975 | M27: =M25*Inputs!$C$51 -> 2.2565491 | ... AD27: =AD25*Inputs!$C$51 -> 0
B28: Principal repayment | C28: ₹ Cr | D28: =SUM(E28:AD28) -> 53.524953 | E28: =IF(E5=Inputs!$C$31,E25,MIN(E25,MAX(0,E23-E27))*E8) -> 0 | F28: =IF(F5=Inputs!$C$31,F25,MIN(F25,MAX(0,F23-F27))*F8) -> 3.4373963 | G28: =IF(G5=Inputs!$C$31,G25,MIN(G25,MAX(0,G23-G27))*G8) -> 3.7549236 | H28: =IF(H5=Inputs!$C$31,H25,MIN(H25,MAX(0,H23-H27))*H8) -> 4.1059648 | I28: =IF(I5=Inputs!$C$31,I25,MIN(I25,MAX(0,I23-I27))*I8) -> 4.4940384 | J28: =IF(J5=Inputs!$C$31,J25,MIN(J25,MAX(0,J23-J27))*J8) -> 4.9230318 | K28: =IF(K5=Inputs!$C$31,K25,MIN(K25,MAX(0,K23-K27))*K8) -> 5.3972411 | L28: =IF(L5=Inputs!$C$31,L25,MIN(L25,MAX(0,L23-L27))*L8) -> 5.9214132 | ... AD28: =IF(AD5=Inputs!$C$31,AD25,MIN(AD25,MAX(0,AD23-AD27))*AD8) -> 0
B29: Closing balance | C29: ₹ Cr | D29: =AD29 -> 0 | E29: =E25+E26-E28 -> 53.524953 | F29: =F25+F26-F28 -> 50.087557 | G29: =G25+G26-G28 -> 46.332633 | H29: =H25+H26-H28 -> 42.226668 | I29: =I25+I26-I28 -> 37.73263 | J29: =J25+J26-J28 -> 32.809598 | K29: =K25+K26-K28 -> 27.412357 | L29: =L25+L26-L28 -> 21.490944 | ... AD29: =AD25+AD26-AD28 -> 0
B30: Senior debt service | C30: ₹ Cr | D30: =SUM(E30:AD30) -> 90.984598 | E30: =E27+E28 -> 2.3417167 | F30: =F27+F28 -> 9.0575163 | G30: =G27+G28 -> 9.014117 | H30: =H27+H28 -> 8.9708913 | I30: =I27+I28 -> 8.9278385 | J30: =J27+J28 -> 8.8849579 | K30: =K27+K28 -> 8.8422489 | L30: =L27+L28 -> 8.7997106 | ... AD30: =AD27+AD28 -> 0
B31: DSCR, P50 (pre-tax) | C31: x | D31: =MIN(E31:AD31) -> 1.4064783 | E31: =IF(E8=1,E16/E30,"") | F31: =IF(F8=1,F16/F30,"") -> 1.4064783 | G31: =IF(G8=1,G16/G30,"") -> 1.406563 | H31: =IF(H8=1,H16/H30,"") -> 1.4066481 | I31: =IF(I8=1,I16/I30,"") -> 1.4067338 | J31: =IF(J8=1,J16/J30,"") -> 1.4068199 | K31: =IF(K8=1,K16/K30,"") -> 1.4069065 | L31: =IF(L8=1,L16/L30,"") -> 1.4069936 | ... AD31: =IF(AD8=1,AD16/AD30,"")
B32: DSCR, P90 (pre-tax) | C32: x | D32: =MIN(E32:AD32) -> 1.3 | E32: =IF(E8=1,E17/E30,"") | F32: =IF(F8=1,F17/F30,"") -> 1.3 | G32: =IF(G8=1,G17/G30,"") -> 1.3 | H32: =IF(H8=1,H17/H30,"") -> 1.3 | I32: =IF(I8=1,I17/I30,"") -> 1.3 | J32: =IF(J8=1,J17/J30,"") -> 1.3 | K32: =IF(K8=1,K17/K30,"") -> 1.3 | L32: =IF(L8=1,L17/L30,"") -> 1.3 | ... AD32: =IF(AD8=1,AD17/AD30,"")
B33: DSCR, P50 (post-tax) | C33: x | D33: =MIN(E33:AD33) -> 1.4064783 | E33: =IF(E8=1,(E16-E46)/E30,"") | F33: =IF(F8=1,(F16-F46)/F30,"") -> 1.4064783 | G33: =IF(G8=1,(G16-G46)/G30,"") -> 1.406563 | H33: =IF(H8=1,(H16-H46)/H30,"") -> 1.4066481 | I33: =IF(I8=1,(I16-I46)/I30,"") -> 1.4067338 | J33: =IF(J8=1,(J16-J46)/J30,"") -> 1.4068199 | K33: =IF(K8=1,(K16-K46)/K30,"") -> 1.4069065 | L33: =IF(L8=1,(L16-L46)/L30,"") -> 1.4069936 | ... AD33: =IF(AD8=1,(AD16-AD46)/AD30,"")
B34: Depreciation and tax
B35: Book value, opening | C35: ₹ Cr | E35: ='Sources & Uses'!$C$43 -> 85.809918 | F35: =E37 -> 82.592047 | G35: =F37 -> 74.869154 | H35: =G37 -> 67.146261 | I35: =H37 -> 59.423369 | J35: =I37 -> 51.700476 | K35: =J37 -> 46.98093 | L35: =K37 -> 42.261385 | M35: =L37 -> 37.541839 | ... AD35: =AC37 -> 0
B36: Book depreciation | C36: ₹ Cr | D36: =SUM(E36:AD36) -> 85.809918 | E36: =MIN(E35,'Sources & Uses'!$C$43*IF(E5<=4,Inputs!$C$22,Inputs!$C$23)*E7) -> 3.2178719 | F36: =MIN(F35,'Sources & Uses'!$C$43*IF(F5<=4,Inputs!$C$22,Inputs!$C$23)*F7) -> 7.7228927 | G36: =MIN(G35,'Sources & Uses'!$C$43*IF(G5<=4,Inputs!$C$22,Inputs!$C$23)*G7) -> 7.7228927 | H36: =MIN(H35,'Sources & Uses'!$C$43*IF(H5<=4,Inputs!$C$22,Inputs!$C$23)*H7) -> 7.7228927 | I36: =MIN(I35,'Sources & Uses'!$C$43*IF(I5<=4,Inputs!$C$22,Inputs!$C$23)*I7) -> 7.7228927 | J36: =MIN(J35,'Sources & Uses'!$C$43*IF(J5<=4,Inputs!$C$22,Inputs!$C$23)*J7) -> 4.7195455 | K36: =MIN(K35,'Sources & Uses'!$C$43*IF(K5<=4,Inputs!$C$22,Inputs!$C$23)*K7) -> 4.7195455 | L36: =MIN(L35,'Sources & Uses'!$C$43*IF(L5<=4,Inputs!$C$22,Inputs!$C$23)*L7) -> 4.7195455 | ... AD36: =MIN(AD35,'Sources & Uses'!$C$43*IF(AD5<=4,Inputs!$C$22,Inputs!$C$23)*AD7) -> 0
B37: Book value, closing | C37: ₹ Cr | E37: =E35-E36 -> 82.592047 | F37: =F35-F36 -> 74.869154 | G37: =G35-G36 -> 67.146261 | H37: =H35-H36 -> 59.423369 | I37: =I35-I36 -> 51.700476 | J37: =J35-J36 -> 46.98093 | K37: =K35-K36 -> 42.261385 | L37: =L35-L36 -> 37.541839 | ... AD37: =AD35-AD36 -> 0
B38: Tax WDV, opening (incl. inverter replacement, added to the block) | C38: ₹ Cr | E38: ='Sources & Uses'!$C$43 -> 85.809918 | F38: =E40+E49 -> 68.647935 | G38: =F40+F49 -> 41.188761 | H38: =G40+G49 -> 24.713257 | I38: =H40+H49 -> 14.827954 | J38: =I40+I49 -> 8.8967723 | K38: =J40+J49 -> 5.3380634 | L38: =K40+K49 -> 3.202838 | M38: =L40+L49 -> 1.9217028 | ... AD38: =AC40+AC49 -> 0.013135644
B39: Tax depreciation | C39: ₹ Cr | D39: =SUM(E39:AD39) -> 91.687037 | E39: =E38*Inputs!$C$24*IF(Inputs!$C$9<6,0.5,1)*IF(Inputs!$C$9>0,1,0) -> 17.161984 | F39: =F38*Inputs!$C$24*IF(F7>0,1,0) -> 27.459174 | G39: =G38*Inputs!$C$24*IF(G7>0,1,0) -> 16.475504 | H39: =H38*Inputs!$C$24*IF(H7>0,1,0) -> 9.8853026 | I39: =I38*Inputs!$C$24*IF(I7>0,1,0) -> 5.9311816 | J39: =J38*Inputs!$C$24*IF(J7>0,1,0) -> 3.5587089 | K39: =K38*Inputs!$C$24*IF(K7>0,1,0) -> 2.1352254 | L39: =L38*Inputs!$C$24*IF(L7>0,1,0) -> 1.2811352 | M39: =M38*Inputs!$C$24*IF(M7>0,1,0) -> 0.76868113 | ... AD39: =AD38*Inputs!$C$24*IF(AD7>0,1,0) -> 0.0052542577
B40: Tax WDV, closing | C40: ₹ Cr | E40: =E38-E39 -> 68.647935 | F40: =F38-F39 -> 41.188761 | G40: =G38-G39 -> 24.713257 | H40: =H38-H39 -> 14.827954 | I40: =I38-I39 -> 8.8967723 | J40: =J38-J39 -> 5.3380634 | K40: =K38-K39 -> 3.202838 | L40: =L38-L39 -> 1.9217028 | ... AD40: =AD38-AD39 -> 0.0078813865
B41: LC fee (if DSRA is an LC) | C41: ₹ Cr | D41: =SUM(E41:AD41) -> 0 | E41: =IF(Inputs!$C$41=2,Inputs!$C$42*Inputs!$C$40/12*F30,0) -> 0 | F41: =IF(Inputs!$C$41=2,Inputs!$C$42*Inputs!$C$40/12*G30,0) -> 0 | G41: =IF(Inputs!$C$41=2,Inputs!$C$42*Inputs!$C$40/12*H30,0) -> 0 | H41: =IF(Inputs!$C$41=2,Inputs!$C$42*Inputs!$C$40/12*I30,0) -> 0 | I41: =IF(Inputs!$C$41=2,Inputs!$C$42*Inputs!$C$40/12*J30,0) -> 0 | J41: =IF(Inputs!$C$41=2,Inputs!$C$42*Inputs!$C$40/12*K30,0) -> 0 | K41: =IF(Inputs!$C$41=2,Inputs!$C$42*Inputs!$C$40/12*L30,0) -> 0 | L41: =IF(Inputs!$C$41=2,Inputs!$C$42*Inputs!$C$40/12*M30,0) -> 0 | ... AC41: =IF(Inputs!$C$41=2,Inputs!$C$42*Inputs!$C$40/12*AD30,0) -> 0 | AD41: 0
...

Sheet SPV4
B1: SPV4 (P4) — Annual operations, senior debt and cash to HoldCo
B2: Year 0 is the construction FY (debt drawn at COD, stub months of operation). Columns E:AD = years 0–25. Column D = total or key result.
B4: Timeline
B5: Year index (0 = construction FY) | D5: Total / result | E5: 0 | F5: =E5+1 -> 1 | G5: =F5+1 -> 2 | H5: =G5+1 -> 3 | I5: =H5+1 -> 4 | J5: =I5+1 -> 5 | K5: =J5+1 -> 6 | L5: =K5+1 -> 7 | M5: =L5+1 -> 8 | ... AD5: =AC5+1 -> 25
B6: Financial year | E6: =Inputs!$D$7+E5 -> 2029 | F6: =Inputs!$D$7+F5 -> 2030 | G6: =Inputs!$D$7+G5 -> 2031 | H6: =Inputs!$D$7+H5 -> 2032 | I6: =Inputs!$D$7+I5 -> 2033 | J6: =Inputs!$D$7+J5 -> 2034 | K6: =Inputs!$D$7+K5 -> 2035 | L6: =Inputs!$D$7+L5 -> 2036 | ... AD6: =Inputs!$D$7+AD5 -> 2054
B7: Operating fraction of year | E7: =IF(E5=0,Inputs!$D$9/12,IF(E5<Inputs!$D$17,1,IF(E5=Inputs!$D$17,1-Inputs!$D$9/12,0))) -> 0.25 | F7: =IF(F5=0,Inputs!$D$9/12,IF(F5<Inputs!$D$17,1,IF(F5=Inputs!$D$17,1-Inputs!$D$9/12,0))) -> 1 | G7: =IF(G5=0,Inputs!$D$9/12,IF(G5<Inputs!$D$17,1,IF(G5=Inputs!$D$17,1-Inputs!$D$9/12,0))) -> 1 | H7: =IF(H5=0,Inputs!$D$9/12,IF(H5<Inputs!$D$17,1,IF(H5=Inputs!$D$17,1-Inputs!$D$9/12,0))) -> 1 | I7: =IF(I5=0,Inputs!$D$9/12,IF(I5<Inputs!$D$17,1,IF(I5=Inputs!$D$17,1-Inputs!$D$9/12,0))) -> 1 | J7: =IF(J5=0,Inputs!$D$9/12,IF(J5<Inputs!$D$17,1,IF(J5=Inputs!$D$17,1-Inputs!$D$9/12,0))) -> 1 | K7: =IF(K5=0,Inputs!$D$9/12,IF(K5<Inputs!$D$17,1,IF(K5=Inputs!$D$17,1-Inputs!$D$9/12,0))) -> 1 | L7: =IF(L5=0,Inputs!$D$9/12,IF(L5<Inputs!$D$17,1,IF(L5=Inputs!$D$17,1-Inputs!$D$9/12,0))) -> 1 | ... AD7: =IF(AD5=0,Inputs!$D$9/12,IF(AD5<Inputs!$D$17,1,IF(AD5=Inputs!$D$17,1-Inputs!$D$9/12,0))) -> 0.75
B8: Repayment flag | E8: =IF(AND(E5>=1,E5<=Inputs!$D$31),1,0) -> 0 | F8: =IF(AND(F5>=1,F5<=Inputs!$D$31),1,0) -> 1 | G8: =IF(AND(G5>=1,G5<=Inputs!$D$31),1,0) -> 1 | H8: =IF(AND(H5>=1,H5<=Inputs!$D$31),1,0) -> 1 | I8: =IF(AND(I5>=1,I5<=Inputs!$D$31),1,0) -> 1 | J8: =IF(AND(J5>=1,J5<=Inputs!$D$31),1,0) -> 1 | K8: =IF(AND(K5>=1,K5<=Inputs!$D$31),1,0) -> 1 | L8: =IF(AND(L5>=1,L5<=Inputs!$D$31),1,0) -> 1 | ... AD8: =IF(AND(AD5>=1,AD5<=Inputs!$D$31),1,0) -> 0
B9: Operations
B10: Degradation factor | E10: =(1-Inputs!$D$15)^MAX(0,E5-1) -> 1 | F10: =(1-Inputs!$D$15)^MAX(0,F5-1) -> 1 | G10: =(1-Inputs!$D$15)^MAX(0,G5-1) -> 0.996 | H10: =(1-Inputs!$D$15)^MAX(0,H5-1) -> 0.992016 | I10: =(1-Inputs!$D$15)^MAX(0,I5-1) -> 0.98804794 | J10: =(1-Inputs!$D$15)^MAX(0,J5-1) -> 0.98409574 | K10: =(1-Inputs!$D$15)^MAX(0,K5-1) -> 0.98015936 | L10: =(1-Inputs!$D$15)^MAX(0,L5-1) -> 0.97623872 | ... AD10: =(1-Inputs!$D$15)^MAX(0,AD5-1) -> 0.90828914
B11: Generation, P50 | C11: MWh | D11: =SUM(E11:AD11) -> 1779876.3 | E11: =Inputs!$D$6*Inputs!$D$14*E10*E7 -> 18650 | F11: =Inputs!$D$6*Inputs!$D$14*F10*F7 -> 74600 | G11: =Inputs!$D$6*Inputs!$D$14*G10*G7 -> 74301.6 | H11: =Inputs!$D$6*Inputs!$D$14*H10*H7 -> 74004.394 | I11: =Inputs!$D$6*Inputs!$D$14*I10*I7 -> 73708.376 | J11: =Inputs!$D$6*Inputs!$D$14*J10*J7 -> 73413.543 | K11: =Inputs!$D$6*Inputs!$D$14*K10*K7 -> 73119.888 | L11: =Inputs!$D$6*Inputs!$D$14*L10*L7 -> 72827.409 | ... AD11: =Inputs!$D$6*Inputs!$D$14*AD10*AD7 -> 50818.777
B12: Generation, P90 | C12: MWh | D12: =SUM(E12:AD12) -> 1665964.2 | E12: =E11*(1-Inputs!$D$39) -> 17456.4 | F12: =F11*(1-Inputs!$D$39) -> 69825.6 | G12: =G11*(1-Inputs!$D$39) -> 69546.298 | H12: =H11*(1-Inputs!$D$39) -> 69268.112 | I12: =I11*(1-Inputs!$D$39) -> 68991.04 | J12: =J11*(1-Inputs!$D$39) -> 68715.076 | K12: =K11*(1-Inputs!$D$39) -> 68440.215 | L12: =L11*(1-Inputs!$D$39) -> 68166.455 | ... AD12: =AD11*(1-Inputs!$D$39) -> 47566.376
